*** Starting uWSGI 2.0.15 (64bit) on [Sun Dec 24 21:52:42 2017] ***
compiled with version: 4.8.5 20150623 (Red Hat 4.8.5-16) on 03 December 2017 18:49:54
os: Linux-3.10.0-514.26.2.el7.x86_64 #1 SMP Tue Jul 4 15:04:05 UTC 2017
nodename: iz2ze09znunwv2igczw02rz
machine: x86_64
clock source: unix
pcre jit disabled
detected number of CPU cores: 1
current working directory: /usr/local/nginx/html/One
detected binary path: /usr/local/bin/uwsgi
uWSGI running as root, you can use --uid/--gid/--chroot options
*** WARNING: you are running uWSGI as root !!! (use the --uid flag) *** 
chdir() to /usr/local/nginx/html/One
your processes number limit is 3897
limiting address space of processes...
your process address space limit is 536870912 bytes (512 MB)
your memory page size is 4096 bytes
detected max file descriptor number: 65535
VirtualHosting mode enabled.
lock engine: pthread robust mutexes
thunder lock: disabled (you can enable it with --thunder-lock)
probably another instance of uWSGI is running on the same address (127.0.0.1:8087).
bind(): Address already in use [core/socket.c line 769]
*** Starting uWSGI 2.0.15 (64bit) on [Sun Dec 24 21:53:35 2017] ***
compiled with version: 4.8.5 20150623 (Red Hat 4.8.5-16) on 03 December 2017 18:49:54
os: Linux-3.10.0-514.26.2.el7.x86_64 #1 SMP Tue Jul 4 15:04:05 UTC 2017
nodename: iz2ze09znunwv2igczw02rz
machine: x86_64
clock source: unix
pcre jit disabled
detected number of CPU cores: 1
current working directory: /usr/local/nginx/html/One
detected binary path: /usr/local/bin/uwsgi
uWSGI running as root, you can use --uid/--gid/--chroot options
*** WARNING: you are running uWSGI as root !!! (use the --uid flag) *** 
chdir() to /usr/local/nginx/html/One
your processes number limit is 3897
limiting address space of processes...
your process address space limit is 536870912 bytes (512 MB)
your memory page size is 4096 bytes
detected max file descriptor number: 65535
VirtualHosting mode enabled.
lock engine: pthread robust mutexes
thunder lock: disabled (you can enable it with --thunder-lock)
uwsgi socket 0 bound to TCP address 127.0.0.1:8087 fd 3
Python version: 3.6.0 (default, Nov 12 2017, 19:32:43)  [GCC 4.8.5 20150623 (Red Hat 4.8.5-16)]
*** Python threads support is disabled. You can enable it with --enable-threads ***
Python main interpreter initialized at 0xb4e010
your server socket listen backlog is limited to 100 connections
your mercy for graceful operations on workers is 60 seconds
mapped 296016 bytes (289 KB) for 2 cores
*** Operational MODE: preforking ***
Traceback (most recent call last):
  File "./One/wsgi.py", line 12, in <module>
    from django.core.wsgi import get_wsgi_application
ModuleNotFoundError: No module named 'django'
unable to load app 0 (mountpoint='') (callable not found or import error)
*** no app loaded. going in full dynamic mode ***
*** uWSGI is running in multiple interpreter mode ***
spawned uWSGI master process (pid: 4240)
spawned uWSGI worker 1 (pid: 4241, cores: 1)
spawned uWSGI worker 2 (pid: 4242, cores: 1)
*** Starting uWSGI 2.0.15 (64bit) on [Sun Dec 24 22:20:59 2017] ***
compiled with version: 4.8.5 20150623 (Red Hat 4.8.5-16) on 03 December 2017 18:49:54
os: Linux-3.10.0-514.26.2.el7.x86_64 #1 SMP Tue Jul 4 15:04:05 UTC 2017
nodename: iz2ze09znunwv2igczw02rz
machine: x86_64
clock source: unix
pcre jit disabled
detected number of CPU cores: 1
current working directory: /usr/local/nginx/html/One
detected binary path: /usr/local/bin/uwsgi
uWSGI running as root, you can use --uid/--gid/--chroot options
*** WARNING: you are running uWSGI as root !!! (use the --uid flag) *** 
chdir() to /usr/local/nginx/html/One
your processes number limit is 3897
limiting address space of processes...
your process address space limit is 536870912 bytes (512 MB)
your memory page size is 4096 bytes
detected max file descriptor number: 65535
VirtualHosting mode enabled.
lock engine: pthread robust mutexes
thunder lock: disabled (you can enable it with --thunder-lock)
uwsgi socket 0 bound to TCP address 127.0.0.1:8087 fd 3
Python version: 3.6.0 (default, Nov 12 2017, 19:32:43)  [GCC 4.8.5 20150623 (Red Hat 4.8.5-16)]
*** Python threads support is disabled. You can enable it with --enable-threads ***
Python main interpreter initialized at 0x27dc010
your server socket listen backlog is limited to 100 connections
your mercy for graceful operations on workers is 60 seconds
mapped 296016 bytes (289 KB) for 2 cores
*** Operational MODE: preforking ***
Traceback (most recent call last):
  File "./One/wsgi.py", line 16, in <module>
    from django.core.wsgi import get_wsgi_application
ModuleNotFoundError: No module named 'django'
unable to load app 0 (mountpoint='') (callable not found or import error)
*** no app loaded. going in full dynamic mode ***
*** uWSGI is running in multiple interpreter mode ***
spawned uWSGI master process (pid: 4468)
spawned uWSGI worker 1 (pid: 4469, cores: 1)
spawned uWSGI worker 2 (pid: 4470, cores: 1)
*** Starting uWSGI 2.0.15 (64bit) on [Sun Dec 24 22:59:06 2017] ***
compiled with version: 4.8.5 20150623 (Red Hat 4.8.5-16) on 03 December 2017 18:49:54
os: Linux-3.10.0-514.26.2.el7.x86_64 #1 SMP Tue Jul 4 15:04:05 UTC 2017
nodename: iz2ze09znunwv2igczw02rz
machine: x86_64
clock source: unix
pcre jit disabled
detected number of CPU cores: 1
current working directory: /usr/local/nginx/html/One
detected binary path: /usr/local/bin/uwsgi
uWSGI running as root, you can use --uid/--gid/--chroot options
*** WARNING: you are running uWSGI as root !!! (use the --uid flag) *** 
chdir() to /usr/local/nginx/html/One
your processes number limit is 3897
limiting address space of processes...
your process address space limit is 536870912 bytes (512 MB)
your memory page size is 4096 bytes
detected max file descriptor number: 65535
VirtualHosting mode enabled.
lock engine: pthread robust mutexes
thunder lock: disabled (you can enable it with --thunder-lock)
uwsgi socket 0 bound to TCP address 127.0.0.1:8087 fd 3
Python version: 3.6.0 (default, Nov 12 2017, 19:32:43)  [GCC 4.8.5 20150623 (Red Hat 4.8.5-16)]
*** Python threads support is disabled. You can enable it with --enable-threads ***
Python main interpreter initialized at 0x2075070
your server socket listen backlog is limited to 100 connections
your mercy for graceful operations on workers is 60 seconds
mapped 296016 bytes (289 KB) for 2 cores
*** Operational MODE: preforking ***
Traceback (most recent call last):
  File "/usr/local/lib/python3.6/site-packages/django/db/backends/sqlite3/base.py", line 31, in <module>
    from pysqlite2 import dbapi2 as Database
ModuleNotFoundError: No module named 'pysqlite2'

During handling of the above exception, another exception occurred:

Traceback (most recent call last):
  File "/usr/local/lib/python3.6/site-packages/django/db/backends/sqlite3/base.py", line 33, in <module>
    from sqlite3 import dbapi2 as Database
  File "/usr/local/lib/python3.6/sqlite3/__init__.py", line 23, in <module>
    from sqlite3.dbapi2 import *
  File "/usr/local/lib/python3.6/sqlite3/dbapi2.py", line 27, in <module>
    from _sqlite3 import *
ModuleNotFoundError: No module named '_sqlite3'

During handling of the above exception, another exception occurred:

Traceback (most recent call last):
  File "./One/wsgi.py", line 16, in <module>
    application = get_wsgi_application()
  File "/usr/local/lib/python3.6/site-packages/django/core/wsgi.py", line 13, in get_wsgi_application
    django.setup(set_prefix=False)
  File "/usr/local/lib/python3.6/site-packages/django/__init__.py", line 27, in setup
    apps.populate(settings.INSTALLED_APPS)
  File "/usr/local/lib/python3.6/site-packages/django/apps/registry.py", line 108, in populate
    app_config.import_models()
  File "/usr/local/lib/python3.6/site-packages/django/apps/config.py", line 202, in import_models
    self.models_module = import_module(models_module_name)
  File "/usr/local/lib/python3.6/importlib/__init__.py", line 126, in import_module
    return _bootstrap._gcd_import(name[level:], package, level)
  File "/usr/local/lib/python3.6/site-packages/django/contrib/auth/models.py", line 4, in <module>
    from django.contrib.auth.base_user import AbstractBaseUser, BaseUserManager
  File "/usr/local/lib/python3.6/site-packages/django/contrib/auth/base_user.py", line 52, in <module>
    class AbstractBaseUser(models.Model):
  File "/usr/local/lib/python3.6/site-packages/django/db/models/base.py", line 124, in __new__
    new_class.add_to_class('_meta', Options(meta, app_label))
  File "/usr/local/lib/python3.6/site-packages/django/db/models/base.py", line 325, in add_to_class
    value.contribute_to_class(cls, name)
  File "/usr/local/lib/python3.6/site-packages/django/db/models/options.py", line 214, in contribute_to_class
    self.db_table = truncate_name(self.db_table, connection.ops.max_name_length())
  File "/usr/local/lib/python3.6/site-packages/django/db/__init__.py", line 33, in __getattr__
    return getattr(connections[DEFAULT_DB_ALIAS], item)
  File "/usr/local/lib/python3.6/site-packages/django/db/utils.py", line 211, in __getitem__
    backend = load_backend(db['ENGINE'])
  File "/usr/local/lib/python3.6/site-packages/django/db/utils.py", line 115, in load_backend
    return import_module('%s.base' % backend_name)
  File "/usr/local/lib/python3.6/importlib/__init__.py", line 126, in import_module
    return _bootstrap._gcd_import(name[level:], package, level)
  File "/usr/local/lib/python3.6/site-packages/django/db/backends/sqlite3/base.py", line 35, in <module>
    raise ImproperlyConfigured("Error loading either pysqlite2 or sqlite3 modules (tried in that order): %s" % exc)
django.core.exceptions.ImproperlyConfigured: Error loading either pysqlite2 or sqlite3 modules (tried in that order): No module named '_sqlite3'
unable to load app 0 (mountpoint='') (callable not found or import error)
*** no app loaded. going in full dynamic mode ***
*** uWSGI is running in multiple interpreter mode ***
spawned uWSGI master process (pid: 4836)
spawned uWSGI worker 1 (pid: 4839, cores: 1)
spawned uWSGI worker 2 (pid: 4840, cores: 1)
*** Starting uWSGI 2.0.15 (64bit) on [Sun Dec 24 23:00:14 2017] ***
compiled with version: 4.8.5 20150623 (Red Hat 4.8.5-16) on 03 December 2017 18:49:54
os: Linux-3.10.0-514.26.2.el7.x86_64 #1 SMP Tue Jul 4 15:04:05 UTC 2017
nodename: iz2ze09znunwv2igczw02rz
machine: x86_64
clock source: unix
pcre jit disabled
detected number of CPU cores: 1
current working directory: /usr/local/nginx/html/One
detected binary path: /usr/local/bin/uwsgi
uWSGI running as root, you can use --uid/--gid/--chroot options
*** WARNING: you are running uWSGI as root !!! (use the --uid flag) *** 
chdir() to /usr/local/nginx/html/One
your processes number limit is 3897
limiting address space of processes...
your process address space limit is 536870912 bytes (512 MB)
your memory page size is 4096 bytes
detected max file descriptor number: 65535
VirtualHosting mode enabled.
lock engine: pthread robust mutexes
thunder lock: disabled (you can enable it with --thunder-lock)
uwsgi socket 0 bound to TCP address 127.0.0.1:8087 fd 3
Python version: 3.6.0 (default, Nov 12 2017, 19:32:43)  [GCC 4.8.5 20150623 (Red Hat 4.8.5-16)]
*** Python threads support is disabled. You can enable it with --enable-threads ***
Python main interpreter initialized at 0xb48070
your server socket listen backlog is limited to 100 connections
your mercy for graceful operations on workers is 60 seconds
mapped 296016 bytes (289 KB) for 2 cores
*** Operational MODE: preforking ***
Traceback (most recent call last):
  File "./One/wsgi.py", line 12, in <module>
    from django.core.wsgi import get_wsgi_application
ModuleNotFoundError: No module named 'django'
unable to load app 0 (mountpoint='') (callable not found or import error)
*** no app loaded. going in full dynamic mode ***
*** uWSGI is running in multiple interpreter mode ***
spawned uWSGI master process (pid: 4857)
spawned uWSGI worker 1 (pid: 4858, cores: 1)
spawned uWSGI worker 2 (pid: 4859, cores: 1)
*** Starting uWSGI 2.0.15 (64bit) on [Sun Dec 24 23:00:55 2017] ***
compiled with version: 4.8.5 20150623 (Red Hat 4.8.5-16) on 03 December 2017 18:49:54
os: Linux-3.10.0-514.26.2.el7.x86_64 #1 SMP Tue Jul 4 15:04:05 UTC 2017
nodename: iz2ze09znunwv2igczw02rz
machine: x86_64
clock source: unix
pcre jit disabled
detected number of CPU cores: 1
current working directory: /usr/local/nginx/html/One
detected binary path: /usr/local/bin/uwsgi
uWSGI running as root, you can use --uid/--gid/--chroot options
*** WARNING: you are running uWSGI as root !!! (use the --uid flag) *** 
chdir() to /usr/local/nginx/html/One
your processes number limit is 3897
limiting address space of processes...
your process address space limit is 536870912 bytes (512 MB)
your memory page size is 4096 bytes
detected max file descriptor number: 65535
VirtualHosting mode enabled.
lock engine: pthread robust mutexes
thunder lock: disabled (you can enable it with --thunder-lock)
uwsgi socket 0 bound to TCP address 127.0.0.1:8087 fd 3
Python version: 3.6.0 (default, Nov 12 2017, 19:32:43)  [GCC 4.8.5 20150623 (Red Hat 4.8.5-16)]
*** Python threads support is disabled. You can enable it with --enable-threads ***
Python main interpreter initialized at 0x2085070
your server socket listen backlog is limited to 100 connections
your mercy for graceful operations on workers is 60 seconds
mapped 296016 bytes (289 KB) for 2 cores
*** Operational MODE: preforking ***
Traceback (most recent call last):

ModuleNotFoundError: No module named 'pysqlite2'

During handling of the above exception, another exception occurred:

Traceback (most recent call last):
  File "/usr/local/lib/python3.6/site-packages/django/db/backends/sqlite3/base.py", line 33, in <module>
    from sqlite3 import dbapi2 as Database
  File "/usr/local/lib/python3.6/sqlite3/__init__.py", line 23, in <module>
    from sqlite3.dbapi2 import *
  File "/usr/local/lib/python3.6/sqlite3/dbapi2.py", line 27, in <module>
    from _sqlite3 import *
ModuleNotFoundError: No module named '_sqlite3'

During handling of the above exception, another exception occurred:

Traceback (most recent call last):
  File "./One/wsgi.py", line 16, in <module>
    application = get_wsgi_application()
  File "/usr/local/lib/python3.6/site-packages/django/core/wsgi.py", line 13, in get_wsgi_application
    django.setup(set_prefix=False)
  File "/usr/local/lib/python3.6/site-packages/django/__init__.py", line 27, in setup
    apps.populate(settings.INSTALLED_APPS)
  File "/usr/local/lib/python3.6/site-packages/django/apps/registry.py", line 108, in populate
    app_config.import_models()
  File "/usr/local/lib/python3.6/site-packages/django/apps/config.py", line 202, in import_models
    self.models_module = import_module(models_module_name)
  File "/usr/local/lib/python3.6/importlib/__init__.py", line 126, in import_module
    return _bootstrap._gcd_import(name[level:], package, level)
  File "/usr/local/lib/python3.6/site-packages/django/contrib/auth/models.py", line 4, in <module>
    from django.contrib.auth.base_user import AbstractBaseUser, BaseUserManager
  File "/usr/local/lib/python3.6/site-packages/django/contrib/auth/base_user.py", line 52, in <module>
    class AbstractBaseUser(models.Model):
  File "/usr/local/lib/python3.6/site-packages/django/db/models/base.py", line 124, in __new__
    new_class.add_to_class('_meta', Options(meta, app_label))
  File "/usr/local/lib/python3.6/site-packages/django/db/models/base.py", line 325, in add_to_class
    value.contribute_to_class(cls, name)
  File "/usr/local/lib/python3.6/site-packages/django/db/models/options.py", line 214, in contribute_to_class
    self.db_table = truncate_name(self.db_table, connection.ops.max_name_length())
  File "/usr/local/lib/python3.6/site-packages/django/db/__init__.py", line 33, in __getattr__
    return getattr(connections[DEFAULT_DB_ALIAS], item)
  File "/usr/local/lib/python3.6/site-packages/django/db/utils.py", line 211, in __getitem__
    backend = load_backend(db['ENGINE'])
  File "/usr/local/lib/python3.6/site-packages/django/db/utils.py", line 115, in load_backend
    return import_module('%s.base' % backend_name)
  File "/usr/local/lib/python3.6/importlib/__init__.py", line 126, in import_module
    return _bootstrap._gcd_import(name[level:], package, level)
  File "/usr/local/lib/python3.6/site-packages/django/db/backends/sqlite3/base.py", line 35, in <module>
    raise ImproperlyConfigured("Error loading either pysqlite2 or sqlite3 modules (tried in that order): %s" % exc)
django.core.exceptions.ImproperlyConfigured: Error loading either pysqlite2 or sqlite3 modules (tried in that order): No module named '_sqlite3'
unable to load app 0 (mountpoint='') (callable not found or import error)
*** no app loaded. going in full dynamic mode ***
*** uWSGI is running in multiple interpreter mode ***
spawned uWSGI master process (pid: 4867)
spawned uWSGI worker 1 (pid: 4869, cores: 1)
spawned uWSGI worker 2 (pid: 4870, cores: 1)
*** Starting uWSGI 2.0.15 (64bit) on [Sun Dec 24 23:05:26 2017] ***
compiled with version: 4.8.5 20150623 (Red Hat 4.8.5-16) on 03 December 2017 18:49:54
os: Linux-3.10.0-514.26.2.el7.x86_64 #1 SMP Tue Jul 4 15:04:05 UTC 2017
nodename: iz2ze09znunwv2igczw02rz
machine: x86_64
clock source: unix
pcre jit disabled
detected number of CPU cores: 1
current working directory: /usr/local/nginx/html/One
detected binary path: /usr/local/bin/uwsgi
uWSGI running as root, you can use --uid/--gid/--chroot options
*** WARNING: you are running uWSGI as root !!! (use the --uid flag) *** 
chdir() to /usr/local/nginx/html/One
your processes number limit is 3897
limiting address space of processes...
your process address space limit is 536870912 bytes (512 MB)
your memory page size is 4096 bytes
detected max file descriptor number: 65535
VirtualHosting mode enabled.
lock engine: pthread robust mutexes
thunder lock: disabled (you can enable it with --thunder-lock)
probably another instance of uWSGI is running on the same address (127.0.0.1:8087).
bind(): Address already in use [core/socket.c line 769]
*** Starting uWSGI 2.0.15 (64bit) on [Sun Dec 24 23:07:17 2017] ***
compiled with version: 4.8.5 20150623 (Red Hat 4.8.5-16) on 03 December 2017 18:49:54
os: Linux-3.10.0-514.26.2.el7.x86_64 #1 SMP Tue Jul 4 15:04:05 UTC 2017
nodename: iz2ze09znunwv2igczw02rz
machine: x86_64
clock source: unix
pcre jit disabled
detected number of CPU cores: 1
current working directory: /usr/local/nginx/html/One
detected binary path: /usr/local/bin/uwsgi
uWSGI running as root, you can use --uid/--gid/--chroot options
*** WARNING: you are running uWSGI as root !!! (use the --uid flag) *** 
chdir() to /usr/local/nginx/html/One
your processes number limit is 3897
limiting address space of processes...
your process address space limit is 536870912 bytes (512 MB)
your memory page size is 4096 bytes
detected max file descriptor number: 65535
VirtualHosting mode enabled.
lock engine: pthread robust mutexes
thunder lock: disabled (you can enable it with --thunder-lock)
uwsgi socket 0 bound to TCP address 127.0.0.1:8087 fd 3
Python version: 3.6.0 (default, Nov 12 2017, 19:32:43)  [GCC 4.8.5 20150623 (Red Hat 4.8.5-16)]
*** Python threads support is disabled. You can enable it with --enable-threads ***
Python main interpreter initialized at 0x1db3070
your server socket listen backlog is limited to 100 connections
your mercy for graceful operations on workers is 60 seconds
mapped 296016 bytes (289 KB) for 2 cores
*** Operational MODE: preforking ***
Traceback (most recent call last):
  File "/usr/local/lib/python3.6/site-packages/django/db/backends/sqlite3/base.py", line 31, in <module>
    from pysqlite2 import dbapi2 as Database
ModuleNotFoundError: No module named 'pysqlite2'

During handling of the above exception, another exception occurred:

Traceback (most recent call last):
  File "/usr/local/lib/python3.6/site-packages/django/db/backends/sqlite3/base.py", line 33, in <module>
    from sqlite3 import dbapi2 as Database
  File "/usr/local/lib/python3.6/sqlite3/__init__.py", line 23, in <module>
    from sqlite3.dbapi2 import *
  File "/usr/local/lib/python3.6/sqlite3/dbapi2.py", line 27, in <module>
    from _sqlite3 import *
ModuleNotFoundError: No module named '_sqlite3'

During handling of the above exception, another exception occurred:

Traceback (most recent call last):
  File "./One/wsgi.py", line 16, in <module>
    application = get_wsgi_application()
  File "/usr/local/lib/python3.6/site-packages/django/core/wsgi.py", line 13, in get_wsgi_application
    django.setup(set_prefix=False)
  File "/usr/local/lib/python3.6/site-packages/django/__init__.py", line 27, in setup
    apps.populate(settings.INSTALLED_APPS)
  File "/usr/local/lib/python3.6/site-packages/django/apps/registry.py", line 108, in populate
    app_config.import_models()
  File "/usr/local/lib/python3.6/site-packages/django/apps/config.py", line 202, in import_models
    self.models_module = import_module(models_module_name)
  File "/usr/local/lib/python3.6/importlib/__init__.py", line 126, in import_module
    return _bootstrap._gcd_import(name[level:], package, level)
  File "/usr/local/lib/python3.6/site-packages/django/contrib/auth/models.py", line 4, in <module>
    from django.contrib.auth.base_user import AbstractBaseUser, BaseUserManager
  File "/usr/local/lib/python3.6/site-packages/django/contrib/auth/base_user.py", line 52, in <module>
    class AbstractBaseUser(models.Model):
  File "/usr/local/lib/python3.6/site-packages/django/db/models/base.py", line 124, in __new__
    new_class.add_to_class('_meta', Options(meta, app_label))
  File "/usr/local/lib/python3.6/site-packages/django/db/models/base.py", line 325, in add_to_class
    value.contribute_to_class(cls, name)
  File "/usr/local/lib/python3.6/site-packages/django/db/models/options.py", line 214, in contribute_to_class
    self.db_table = truncate_name(self.db_table, connection.ops.max_name_length())
  File "/usr/local/lib/python3.6/site-packages/django/db/__init__.py", line 33, in __getattr__
    return getattr(connections[DEFAULT_DB_ALIAS], item)
  File "/usr/local/lib/python3.6/site-packages/django/db/utils.py", line 211, in __getitem__
    backend = load_backend(db['ENGINE'])
  File "/usr/local/lib/python3.6/site-packages/django/db/utils.py", line 115, in load_backend
    return import_module('%s.base' % backend_name)
  File "/usr/local/lib/python3.6/importlib/__init__.py", line 126, in import_module
    return _bootstrap._gcd_import(name[level:], package, level)
  File "/usr/local/lib/python3.6/site-packages/django/db/backends/sqlite3/base.py", line 35, in <module>
    raise ImproperlyConfigured("Error loading either pysqlite2 or sqlite3 modules (tried in that order): %s" % exc)
django.core.exceptions.ImproperlyConfigured: Error loading either pysqlite2 or sqlite3 modules (tried in that order): No module named '_sqlite3'
unable to load app 0 (mountpoint='') (callable not found or import error)
*** no app loaded. going in full dynamic mode ***
*** uWSGI is running in multiple interpreter mode ***
spawned uWSGI master process (pid: 4930)
spawned uWSGI worker 1 (pid: 4932, cores: 1)
spawned uWSGI worker 2 (pid: 4933, cores: 1)
*** Starting uWSGI 2.0.15 (64bit) on [Sun Dec 24 23:25:38 2017] ***
compiled with version: 4.8.5 20150623 (Red Hat 4.8.5-16) on 03 December 2017 18:49:54
os: Linux-3.10.0-514.26.2.el7.x86_64 #1 SMP Tue Jul 4 15:04:05 UTC 2017
nodename: iz2ze09znunwv2igczw02rz
machine: x86_64
clock source: unix
pcre jit disabled
detected number of CPU cores: 1
current working directory: /usr/local/nginx/html/One
detected binary path: /usr/local/bin/uwsgi
uWSGI running as root, you can use --uid/--gid/--chroot options
*** WARNING: you are running uWSGI as root !!! (use the --uid flag) *** 
chdir() to /usr/local/nginx/html/One
your processes number limit is 3897
limiting address space of processes...
your process address space limit is 536870912 bytes (512 MB)
your memory page size is 4096 bytes
detected max file descriptor number: 65535
VirtualHosting mode enabled.
lock engine: pthread robust mutexes
thunder lock: disabled (you can enable it with --thunder-lock)
uwsgi socket 0 bound to TCP address 127.0.0.1:8087 fd 3
Python version: 3.6.0 (default, Nov 12 2017, 19:32:43)  [GCC 4.8.5 20150623 (Red Hat 4.8.5-16)]
*** Python threads support is disabled. You can enable it with --enable-threads ***
Python main interpreter initialized at 0xcb5060
your server socket listen backlog is limited to 100 connections
your mercy for graceful operations on workers is 60 seconds
mapped 296016 bytes (289 KB) for 2 cores
*** Operational MODE: preforking ***
Traceback (most recent call last):
  File "/usr/local/lib/python3.6/site-packages/django/db/backends/sqlite3/base.py", line 31, in <module>
    from pysqlite2 import dbapi2 as Database
ModuleNotFoundError: No module named 'pysqlite2'

During handling of the above exception, another exception occurred:

Traceback (most recent call last):
  File "/usr/local/lib/python3.6/site-packages/django/db/backends/sqlite3/base.py", line 33, in <module>
    from sqlite3 import dbapi2 as Database
  File "/usr/local/lib/python3.6/sqlite3/__init__.py", line 23, in <module>
    from sqlite3.dbapi2 import *
  File "/usr/local/lib/python3.6/sqlite3/dbapi2.py", line 27, in <module>
    from _sqlite3 import *
ImportError: dynamic module does not define module export function (PyInit__sqlite3)

During handling of the above exception, another exception occurred:

Traceback (most recent call last):
  File "./One/wsgi.py", line 16, in <module>
    application = get_wsgi_application()
  File "/usr/local/lib/python3.6/site-packages/django/core/wsgi.py", line 13, in get_wsgi_application
    django.setup(set_prefix=False)
  File "/usr/local/lib/python3.6/site-packages/django/__init__.py", line 27, in setup
    apps.populate(settings.INSTALLED_APPS)
  File "/usr/local/lib/python3.6/site-packages/django/apps/registry.py", line 108, in populate
    app_config.import_models()
  File "/usr/local/lib/python3.6/site-packages/django/apps/config.py", line 202, in import_models
    self.models_module = import_module(models_module_name)
  File "/usr/local/lib/python3.6/importlib/__init__.py", line 126, in import_module
    return _bootstrap._gcd_import(name[level:], package, level)
  File "/usr/local/lib/python3.6/site-packages/django/contrib/auth/models.py", line 4, in <module>
    from django.contrib.auth.base_user import AbstractBaseUser, BaseUserManager
  File "/usr/local/lib/python3.6/site-packages/django/contrib/auth/base_user.py", line 52, in <module>
    class AbstractBaseUser(models.Model):
  File "/usr/local/lib/python3.6/site-packages/django/db/models/base.py", line 124, in __new__
    new_class.add_to_class('_meta', Options(meta, app_label))
  File "/usr/local/lib/python3.6/site-packages/django/db/models/base.py", line 325, in add_to_class
    value.contribute_to_class(cls, name)
  File "/usr/local/lib/python3.6/site-packages/django/db/models/options.py", line 214, in contribute_to_class
    self.db_table = truncate_name(self.db_table, connection.ops.max_name_length())
  File "/usr/local/lib/python3.6/site-packages/django/db/__init__.py", line 33, in __getattr__
    return getattr(connections[DEFAULT_DB_ALIAS], item)
  File "/usr/local/lib/python3.6/site-packages/django/db/utils.py", line 211, in __getitem__
    backend = load_backend(db['ENGINE'])
  File "/usr/local/lib/python3.6/site-packages/django/db/utils.py", line 115, in load_backend
    return import_module('%s.base' % backend_name)
  File "/usr/local/lib/python3.6/importlib/__init__.py", line 126, in import_module
    return _bootstrap._gcd_import(name[level:], package, level)
  File "/usr/local/lib/python3.6/site-packages/django/db/backends/sqlite3/base.py", line 35, in <module>
    raise ImproperlyConfigured("Error loading either pysqlite2 or sqlite3 modules (tried in that order): %s" % exc)
django.core.exceptions.ImproperlyConfigured: Error loading either pysqlite2 or sqlite3 modules (tried in that order): dynamic module does not define module export function (PyInit__sqlite3)
unable to load app 0 (mountpoint='') (callable not found or import error)
*** no app loaded. going in full dynamic mode ***
*** uWSGI is running in multiple interpreter mode ***
spawned uWSGI master process (pid: 5146)
spawned uWSGI worker 1 (pid: 5148, cores: 1)
spawned uWSGI worker 2 (pid: 5149, cores: 1)
*** Starting uWSGI 2.0.15 (64bit) on [Sun Dec 24 23:52:09 2017] ***
compiled with version: 4.8.5 20150623 (Red Hat 4.8.5-16) on 03 December 2017 18:49:54
os: Linux-3.10.0-514.26.2.el7.x86_64 #1 SMP Tue Jul 4 15:04:05 UTC 2017
nodename: iz2ze09znunwv2igczw02rz
machine: x86_64
clock source: unix
pcre jit disabled
detected number of CPU cores: 1
current working directory: /usr/local/nginx/html/One
detected binary path: /usr/local/bin/uwsgi
uWSGI running as root, you can use --uid/--gid/--chroot options
*** WARNING: you are running uWSGI as root !!! (use the --uid flag) *** 
chdir() to /usr/local/nginx/html/One
your processes number limit is 3897
limiting address space of processes...
your process address space limit is 536870912 bytes (512 MB)
your memory page size is 4096 bytes
detected max file descriptor number: 65535
VirtualHosting mode enabled.
lock engine: pthread robust mutexes
thunder lock: disabled (you can enable it with --thunder-lock)
uwsgi socket 0 bound to TCP address 127.0.0.1:8087 fd 3
Python version: 3.6.0 (default, Nov 12 2017, 19:32:43)  [GCC 4.8.5 20150623 (Red Hat 4.8.5-16)]
*** Python threads support is disabled. You can enable it with --enable-threads ***
Python main interpreter initialized at 0x213e060
your server socket listen backlog is limited to 100 connections
your mercy for graceful operations on workers is 60 seconds
mapped 296016 bytes (289 KB) for 2 cores
*** Operational MODE: preforking ***
WSGI app 0 (mountpoint='') ready in 1 seconds on interpreter 0x213e060 pid: 16570 (default app)
*** uWSGI is running in multiple interpreter mode ***
spawned uWSGI master process (pid: 16570)
spawned uWSGI worker 1 (pid: 16572, cores: 1)
spawned uWSGI worker 2 (pid: 16573, cores: 1)
*** Starting uWSGI 2.0.15 (64bit) on [Sun Dec 24 23:59:06 2017] ***
compiled with version: 4.8.5 20150623 (Red Hat 4.8.5-16) on 03 December 2017 18:49:54
os: Linux-3.10.0-514.26.2.el7.x86_64 #1 SMP Tue Jul 4 15:04:05 UTC 2017
nodename: iz2ze09znunwv2igczw02rz
machine: x86_64
clock source: unix
pcre jit disabled
detected number of CPU cores: 1
current working directory: /usr/local/nginx/html/One
detected binary path: /usr/local/bin/uwsgi
uWSGI running as root, you can use --uid/--gid/--chroot options
*** WARNING: you are running uWSGI as root !!! (use the --uid flag) *** 
chdir() to /usr/local/nginx/html/One
your processes number limit is 3897
limiting address space of processes...
your process address space limit is 536870912 bytes (512 MB)
your memory page size is 4096 bytes
detected max file descriptor number: 65535
VirtualHosting mode enabled.
lock engine: pthread robust mutexes
thunder lock: disabled (you can enable it with --thunder-lock)
uwsgi socket 0 bound to TCP address 127.0.0.1:8087 fd 3
Python version: 3.6.0 (default, Nov 12 2017, 19:32:43)  [GCC 4.8.5 20150623 (Red Hat 4.8.5-16)]
*** Python threads support is disabled. You can enable it with --enable-threads ***
Python main interpreter initialized at 0x23c8070
your server socket listen backlog is limited to 100 connections
your mercy for graceful operations on workers is 60 seconds
mapped 296016 bytes (289 KB) for 2 cores
*** Operational MODE: preforking ***
Traceback (most recent call last):
  File "./One/wsgi.py", line 16, in <module>
    application = get_wsgi_application()
  File "/usr/local/lib/python3.6/site-packages/django/core/wsgi.py", line 13, in get_wsgi_application
    django.setup(set_prefix=False)
  File "/usr/local/lib/python3.6/site-packages/django/__init__.py", line 22, in setup
    configure_logging(settings.LOGGING_CONFIG, settings.LOGGING)
  File "/usr/local/lib/python3.6/site-packages/django/conf/__init__.py", line 56, in __getattr__
    self._setup(name)
  File "/usr/local/lib/python3.6/site-packages/django/conf/__init__.py", line 41, in _setup
    self._wrapped = Settings(settings_module)
  File "/usr/local/lib/python3.6/site-packages/django/conf/__init__.py", line 110, in __init__
    mod = importlib.import_module(self.SETTINGS_MODULE)
  File "/usr/local/lib/python3.6/importlib/__init__.py", line 126, in import_module
    return _bootstrap._gcd_import(name[level:], package, level)
  File "./One/settings.py", line 28
    ALLOWED_HOSTS = [123.56.19.63]
                             ^
SyntaxError: invalid syntax
unable to load app 0 (mountpoint='') (callable not found or import error)
*** no app loaded. going in full dynamic mode ***
*** uWSGI is running in multiple interpreter mode ***
spawned uWSGI master process (pid: 16742)
spawned uWSGI worker 1 (pid: 16744, cores: 1)
spawned uWSGI worker 2 (pid: 16745, cores: 1)
Traceback (most recent call last):
  File "./One/wsgi.py", line 16, in <module>
    application = get_wsgi_application()
  File "/usr/local/lib/python3.6/site-packages/django/core/wsgi.py", line 13, in get_wsgi_application
    django.setup(set_prefix=False)
  File "/usr/local/lib/python3.6/site-packages/django/__init__.py", line 22, in setup
    configure_logging(settings.LOGGING_CONFIG, settings.LOGGING)
  File "/usr/local/lib/python3.6/site-packages/django/conf/__init__.py", line 56, in __getattr__
    self._setup(name)
  File "/usr/local/lib/python3.6/site-packages/django/conf/__init__.py", line 41, in _setup
    self._wrapped = Settings(settings_module)
  File "/usr/local/lib/python3.6/site-packages/django/conf/__init__.py", line 110, in __init__
    mod = importlib.import_module(self.SETTINGS_MODULE)
  File "/usr/local/lib/python3.6/importlib/__init__.py", line 126, in import_module
    return _bootstrap._gcd_import(name[level:], package, level)
  File "./One/settings.py", line 28
    ALLOWED_HOSTS = [123.56.19.63]
                             ^
SyntaxError: invalid syntax
unable to load app 0 (mountpoint='123.56.19.63:8084|') (callable not found or import error)
--- no python application found, check your startup logs for errors ---
123.56.19.63:8084 [pid: 16744|app: -1|req: -1/1] 222.222.106.66 () {48 vars in 828 bytes} [Sun Dec 24 23:59:08 2017] GET / => generated 21 bytes in 2 msecs (HTTP/1.1 500) 2 headers in 83 bytes (0 switches on core 0)
Traceback (most recent call last):
  File "./One/wsgi.py", line 16, in <module>
    application = get_wsgi_application()
  File "/usr/local/lib/python3.6/site-packages/django/core/wsgi.py", line 13, in get_wsgi_application
    django.setup(set_prefix=False)
  File "/usr/local/lib/python3.6/site-packages/django/__init__.py", line 22, in setup
    configure_logging(settings.LOGGING_CONFIG, settings.LOGGING)
  File "/usr/local/lib/python3.6/site-packages/django/conf/__init__.py", line 56, in __getattr__
    self._setup(name)
  File "/usr/local/lib/python3.6/site-packages/django/conf/__init__.py", line 41, in _setup
    self._wrapped = Settings(settings_module)
  File "/usr/local/lib/python3.6/site-packages/django/conf/__init__.py", line 110, in __init__
    mod = importlib.import_module(self.SETTINGS_MODULE)
  File "/usr/local/lib/python3.6/importlib/__init__.py", line 126, in import_module
    return _bootstrap._gcd_import(name[level:], package, level)
  File "./One/settings.py", line 28
    ALLOWED_HOSTS = [123.56.19.63]
                             ^
SyntaxError: invalid syntax
unable to load app 0 (mountpoint='123.56.19.63:8084|') (callable not found or import error)
--- no python application found, check your startup logs for errors ---
123.56.19.63:8084 [pid: 16745|app: -1|req: -1/2] 222.222.106.66 () {48 vars in 828 bytes} [Sun Dec 24 23:59:10 2017] GET / => generated 21 bytes in 2 msecs (HTTP/1.1 500) 2 headers in 83 bytes (0 switches on core 0)
